<?xml version="1.0" ?>
<robot xmlns:xacro="http://ros.org/wiki/xacro" name="four_bar_linkage">

<xacro:property name="h" value="0.03" />
<xacro:property name="w" value="0.4" />
<xacro:property name="d" value="0.03" />
<xacro:property name="m" value="1." />
<xacro:property name="PI" value="3.1415" />

<link name="world"/>

<link name="base_link">
	<inertial>
		<origin rpy="0 0 0" xyz="0 0 0"/>
		<mass value="${m}"/>
		<inertia ixx="${(m/12.) * (h**2 + w**2)}" ixy="0." ixz="0." iyy="${(m/12.) * (h**2 + d**2)}" iyz="0." izz="${(m/12.) * (w**2 + d**2)}"/>
	</inertial>
	<visual>
		<origin rpy="0 0 0" xyz="0 0 0"/>
		<material name=""/>
		<geometry name="">
			<box size="${d} ${w} ${h}"/>
		</geometry>
	</visual>
	<collision>
		<origin rpy="0 0 0" xyz="0 0 0"/>
		<geometry name="">
			<box size="${d} ${w} ${h}"/>
		</geometry>
	</collision>
</link>

<link name="link1">
	<inertial>
		<origin rpy="0 0 0" xyz="0 ${-w/2.} 0"/>
		<mass value="${m}"/>
		<inertia ixx="${(m/12.) * (h**2 + w**2)}" ixy="0." ixz="0." iyy="${(m/12.) * (h**2 + d**2)}" iyz="0." izz="${(m/12.) * (w**2 + d**2)}"/>
	</inertial>
	<visual>
		<origin rpy="0 0 0" xyz="0 ${-w/2.} 0"/>
		<material name=""/>
		<geometry name="">
			<box size="${d} ${w} ${h}"/>
		</geometry>
	</visual>
	<collision>
		<origin rpy="0 0 0" xyz="0 ${-w/2.} 0"/>
		<geometry name="">
			<box size="${d} ${w} ${h}"/>
		</geometry>
	</collision>
</link>

<link name="link2">
	<inertial>
		<origin rpy="0 0 0" xyz="0 ${-w/2.} 0"/>
		<mass value="${m}"/>
		<inertia ixx="${(m/12.) * (h**2 + w**2)}" ixy="0." ixz="0." iyy="${(m/12.) * (h**2 + d**2)}" iyz="0." izz="${(m/12.) * (w**2 + d**2)}"/>
	</inertial>
	<visual>
		<origin rpy="0 0 0" xyz="0 ${-w/2.} 0"/>
		<material name=""/>
		<geometry name="">
			<box size="${d} ${w} ${h}"/>
		</geometry>
	</visual>
	<collision>
		<origin rpy="0 0 0" xyz="0 ${-w/2.} 0"/>
		<geometry name="">
			<box size="${d} ${w} ${h}"/>
		</geometry>
	</collision>
</link>

<link name="link3">
	<inertial>
		<origin rpy="0 0 0" xyz="0 ${-w/2.} 0"/>
		<mass value="${m}"/>
		<inertia ixx="${(m/12.) * (h**2 + w**2)}" ixy="0." ixz="0." iyy="${(m/12.) * (h**2 + d**2)}" iyz="0." izz="${(m/12.) * (w**2 + d**2)}"/>
	</inertial>
	<visual>
		<origin rpy="0 0 0" xyz="0 ${-w/2.} 0"/>
		<material name=""/>
		<geometry name="">
			<box size="${d} ${w} ${h}"/>
		</geometry>
	</visual>
	<collision>
		<origin rpy="0 0 0" xyz="0 ${-w/2.} 0"/>
		<geometry name="">
			<box size="${d} ${w} ${h}"/>
		</geometry>
	</collision>
</link>

<link name="frame0"/>
<link name="frame1"/>

<joint name="base_joint" type="fixed">
	<parent link="world"/>
	<child link="base_link"/>
	<origin rpy="0 0 0" xyz="0 0 0"/>
</joint>

<joint name="Joint1" type="revolute">
	<parent link="base_link"/>
	<child link="link1"/>
	<origin rpy="${-PI/2.} 0 0" xyz="0 ${-w/2.} 0"/>
	<axis xyz="1 0 0"/>
	<limit effort="140" lower="${-PI}" upper="${PI}" velocity="10."/>
</joint>
 
<joint name="Joint2" type="revolute">
	<parent link="link1"/>
	<child link="link2"/>
	<origin rpy="${-PI/2.} 0 0" xyz="0 ${-w} 0"/>
	<axis xyz="1 0 0"/>
	<limit effort="140" lower="${-PI}" upper="${PI}" velocity="10."/>
</joint>

<joint name="Joint3" type="revolute">
	<parent link="base_link"/>
	<child link="link3"/>
	<origin rpy="${-PI/2.} 0 0" xyz="0 ${w/2.} 0"/>
	<axis xyz="1 0 0"/>
	<limit effort="140" lower="${-PI}" upper="${PI}" velocity="10."/>
</joint>

<joint name="Joint4" type="fixed">
	<parent link="link3"/>
	<child link="frame0"/>
	<origin rpy="0 0 0" xyz="0 ${-w} 0"/>
</joint>

<joint name="Joint5" type="fixed">
	<parent link="link2"/>
	<child link="frame1"/>
	<origin rpy="0 0 0" xyz="0 ${-w} 0"/>
</joint>


</robot>

